Workbook

Sheet CFG
A1: 1 | B1: <program> | C1: ="=>" -> => | D1: <global_dec> | E1: <function> | F1: <main_func>
A2: 2 | B2: <global_dec> | C2: ="=>" -> => | D2: global | E2: <mutability> | F2: ; | G2: <global_dec>
A3: 3 | B3: <global_dec> | C3: ="=>" -> => | D3: <weave_def> | E3: <global_dec>
A4: 4 | B4: <global_dec> | C4: ="=>" -> => | D4: λ
A5: 5 | B5: <mutability> | C5: ="=>" -> => | D5: var | E5: <var_or_weave>
A6: 6 | B6: <mutability> | C6: ="=>" -> => | D6: const | E6: <const_weave>
A7: 7 | B7: <var_or_weave> | C7: ="=>" -> => | D7: <dtype> | E7: id | F7: <var_or_arr>
A8: 8 | B8: <var_or_weave> | C8: ="=>" -> => | D8: id | E8: id | F8: = | G8: { | H8: <weave_init_list> | I8: }
A9: 9 | B9: <const_weave> | C9: ="=>" -> => | D9: <dtype> | E9: id | F9: <const_or_arr>
A10: 10 | B10: <const_weave> | C10: ="=>" -> => | D10: id | E10: id | F10: = | G10: { | H10: <weave_init_list> | I10: }
A11: 11 | B11: <dtype> | C11: ="=>" -> => | D11: int
A12: 12 | B12: <dtype> | C12: ="=>" -> => | D12: long
A13: 13 | B13: <dtype> | C13: ="=>" -> => | D13: float
A14: 14 | B14: <dtype> | C14: ="=>" -> => | D14: double
A15: 15 | B15: <dtype> | C15: ="=>" -> => | D15: char
A16: 16 | B16: <dtype> | C16: ="=>" -> => | D16: string
A17: 17 | B17: <dtype> | C17: ="=>" -> => | D17: bool
A18: 18 | B18: <var_or_arr> | C18: ="=>" -> => | D18: = | E18: <value> | F18: <multi_dec>
A19: 19 | B19: <var_or_arr> | C19: ="=>" -> => | D19: [ | E19: <size> | F19: ] | G19: <var_1D_or_2D>
A20: 20 | B20: <const_or_arr> | C20: ="=>" -> => | D20: = | E20: <literals_num> | F20: <multi_dec_const>
A21: 21 | B21: <const_or_arr> | C21: ="=>" -> => | D21: [ | E21: <size> | F21: ] | G21: <const_1D_or_2D>
A22: 22 | B22: <value> | C22: ="=>" -> => | D22: <string_or_logical_expr>
A23: 23 | B23: <multi_dec> | C23: ="=>" -> => | D23: , | E23: id | F23: = | G23: <value> | H23: <multi_dec>
A24: 24 | B24: <multi_dec> | C24: ="=>" -> => | D24: λ
A25: 25 | B25: <multi_dec_const> | C25: ="=>" -> => | D25: , | E25: id | F25: = | G25: <literals_num> | H25: <multi_dec_const>
A26: 26 | B26: <multi_dec_const> | C26: ="=>" -> => | D26: λ
A27: 27 | B27: <size> | C27: ="=>" -> => | D27: intlit
A28: 28 | B28: <size> | C28: ="=>" -> => | D28: id
A29: 29 | B29: <literals_num> | C29: ="=>" -> => | D29: <literals>
A30: 30 | B30: <literals_num> | C30: ="=>" -> => | D30: - | E30: <num_lit>
A31: 31 | B31: <num_lit> | C31: ="=>" -> => | D31: intlit
A32: 32 | B32: <num_lit> | C32: ="=>" -> => | D32: longlit
A33: 33 | B33: <num_lit> | C33: ="=>" -> => | D33: floatlit
A34: 34 | B34: <num_lit> | C34: ="=>" -> => | D34: doublelit
A35: 35 | B35: <var_1D_or_2D> | C35: ="=>" -> => | D35: = | E35: { | F35: <1D_elem_list> | G35: }
A36: 36 | B36: <var_1D_or_2D> | C36: ="=>" -> => | D36: [ | E36: <size> | F36: ] | G36: <arr_2D_init_opt>
A37: 37 | B37: <var_1D_or_2D> | C37: ="=>" -> => | D37: λ
A38: 38 | B38: <1D_elem_list> | C38: ="=>" -> => | D38: <elem_value> | E38: <1D_elem_list_tail>
A39: 39 | B39: <elem_value> | C39: ="=>" -> => | D39: <literals>
A40: 40 | B40: <elem_value> | C40: ="=>" -> => | D40: id
...

Sheet First Set Macro
A1: 1 | B1: <program> | C1: => | D1: ="{ " & TEXTJOIN(", ", TRUE, F1:AB1) & " }" -> { global , weave, func, int } | E1: First(<program>) | F1: global | G1: weave | H1: func | I1: int
A2: 2 | B2: <global_dec> | C2: => | D2: ="{ " & TEXTJOIN(", ", TRUE, F2:AB2) & " }" -> { global , weave, λ } | E2: First(<global_dec>) | F2: global | G2: weave | H2: λ
A3: 3 | B3: <mutability> | C3: => | D3: ="{ " & TEXTJOIN(", ", TRUE, F3:AB3) & " }" -> { var, const } | E3: First(<mutability>) | F3: var | G3: const
A4: 4 | B4: <var_or_weave> | C4: => | D4: ="{ " & TEXTJOIN(", ", TRUE, F4:AB4) & " }" -> { int, long, float, double, char, string, bool, id } | E4: First(<var_or_weave>) | F4: int | G4: long | H4: float | I4: double | J4: char | K4: string | L4: bool | M4: id
A5: 5 | B5: <const_weave> | C5: => | D5: ="{ " & TEXTJOIN(", ", TRUE, F5:AB5) & " }" -> { int, long, float, double, char, string, bool, id } | E5: First(<const_weave>) | F5: int | G5: long | H5: float | I5: double | J5: char | K5: string | L5: bool | M5: id
A6: 6 | B6: <dtype> | C6: => | D6: ="{ " & TEXTJOIN(", ", TRUE, F6:AB6) & " }" -> { int, long, float, double, char, string, bool } | E6: First(<dtype>) | F6: int | G6: long | H6: float | I6: double | J6: char | K6: string | L6: bool
A7: 7 | B7: <var_or_arr> | C7: => | D7: ="{ " & TEXTJOIN(", ", TRUE, F7:AB7) & " }" -> { =, [ } | E7: First(<var_or_arr>) | F7: = | G7: [
A8: 8 | B8: <const_or_arr> | C8: => | D8: ="{ " & TEXTJOIN(", ", TRUE, F8:AB8) & " }" -> { =, [ } | E8: First(<const_or_arr>) | F8: = | G8: [
A9: 9 | B9: <value> | C9: => | D9: ="{ " & TEXTJOIN(", ", TRUE, F9:AB9) & " }" -> { !, id, intlit, longlit, floatlit, doublelit, charlit, stringlit, true, false, abs, len, pow, sqrt, -, ( } | E9: First(<value>) | F9: ! | G9: id | H9: intlit | I9: longlit | J9: floatlit | K9: doublelit | L9: charlit | M9: stringlit | N9: true | O9: false | P9: abs | Q9: len | R9: pow | S9: sqrt | T9: - | U9: (
A10: 10 | B10: <multi_dec> | C10: => | D10: ="{ " & TEXTJOIN(", ", TRUE, F10:AB10) & " }" -> { ,, λ } | E10: First(<multi_dec>) | F10: , | G10: λ
A11: 11 | B11: <multi_dec_const> | C11: => | D11: ="{ " & TEXTJOIN(", ", TRUE, F11:AB11) & " }" -> { ,, λ } | E11: First(<multi_dec_const>) | F11: , | G11: λ
A12: 12 | B12: <size> | C12: => | D12: ="{ " & TEXTJOIN(", ", TRUE, F12:AB12) & " }" -> { intlit, id } | E12: First(<size>) | F12: intlit | G12: id
A13: 13 | B13: <literals_num> | C13: => | D13: ="{ " & TEXTJOIN(", ", TRUE, F13:AB13) & " }" -> { intlit, longlit, floatlit, doublelit, charlit, stringlit, true, false, - } | E13: First(<literals_num>) | F13: intlit | G13: longlit | H13: floatlit | I13: doublelit | J13: charlit | K13: stringlit | L13: true | M13: false | N13: -
A14: 14 | B14: <num_lit> | C14: => | D14: ="{ " & TEXTJOIN(", ", TRUE, F14:AB14) & " }" -> { intlit, longlit, floatlit, doublelit } | E14: First(<num_lit>) | F14: intlit | G14: longlit | H14: floatlit | I14: doublelit
A15: 15 | B15: <var_1D_or_2D> | C15: => | D15: ="{ " & TEXTJOIN(", ", TRUE, F15:AB15) & " }" -> { =, [, λ } | E15: First(<var_1D_or_2D>) | F15: = | G15: [ | H15: λ
A16: 16 | B16: <1D_elem_list> | C16: => | D16: ="{ " & TEXTJOIN(", ", TRUE, F16:AB16) & " }" -> { intlit, longlit, floatlit, doublelit, charlit, stringlit, true, false, id } | E16: First(<1D_elem_list>) | F16: intlit | G16: longlit | H16: floatlit | I16: doublelit | J16: charlit | K16: stringlit | L16: true | M16: false | N16: id
A17: 17 | B17: <elem_value> | C17: => | D17: ="{ " & TEXTJOIN(", ", TRUE, F17:AB17) & " }" -> { intlit, longlit, floatlit, doublelit, charlit, stringlit, true, false, id } | E17: First(<elem_value>) | F17: intlit | G17: longlit | H17: floatlit | I17: doublelit | J17: charlit | K17: stringlit | L17: true | M17: false | N17: id
A18: 18 | B18: <1D_elem_list_tail> | C18: => | D18: ="{ " & TEXTJOIN(", ", TRUE, F18:AB18) & " }" -> { ,, λ } | E18: First(<1D_elem_list_tail>) | F18: , | G18: λ
A19: 19 | B19: <arr_2D_init_opt> | C19: => | D19: ="{ " & TEXTJOIN(", ", TRUE, F19:AB19) & " }" -> { =, λ } | E19: First(<arr_2D_init_opt>) | F19: = | G19: λ
A20: 20 | B20: <arr_2D_init> | C20: => | D20: ="{ " & TEXTJOIN(", ", TRUE, F20:AB20) & " }" -> { = } | E20: First(<arr_2D_init>) | F20: =
A21: 21 | B21: <2D_elem_list> | C21: => | D21: ="{ " & TEXTJOIN(", ", TRUE, F21:AB21) & " }" -> { { } | E21: First(<2D_elem_list>) | F21: {
A22: 22 | B22: <2D_elem_list_cont> | C22: => | D22: ="{ " & TEXTJOIN(", ", TRUE, F22:AB22) & " }" -> { ,, λ } | E22: First(<2D_elem_list_cont>) | F22: , | G22: λ
A23: 23 | B23: <const_1D_or_2D> | C23: => | D23: ="{ " & TEXTJOIN(", ", TRUE, F23:AB23) & " }" -> { =, [ } | E23: First(<const_1D_or_2D>) | F23: = | G23: [
A24: 24 | B24: <weave_init_list> | C24: => | D24: ="{ " & TEXTJOIN(", ", TRUE, F24:AB24) & " }" -> { intlit, longlit, floatlit, doublelit, charlit, stringlit, true, false, -, id } | E24: First(<weave_init_list>) | F24: intlit | G24: longlit | H24: floatlit | I24: doublelit | J24: charlit | K24: stringlit | L24: true | M24: false | N24: - | O24: id
A25: 25 | B25: <weave_elem> | C25: => | D25: ="{ " & TEXTJOIN(", ", TRUE, F25:AB25) & " }" -> { intlit, longlit, floatlit, doublelit, charlit, stringlit, true, false, -, id } | E25: First(<weave_elem>) | F25: intlit | G25: longlit | H25: floatlit | I25: doublelit | J25: charlit | K25: stringlit | L25: true | M25: false | N25: - | O25: id
A26: 26 | B26: <weave_init_list_tail> | C26: => | D26: ="{ " & TEXTJOIN(", ", TRUE, F26:AB26) & " }" -> { ,, λ } | E26: First(<weave_init_list_tail>) | F26: , | G26: λ
A27: 27 | B27: <weave_def> | C27: => | D27: ="{ " & TEXTJOIN(", ", TRUE, F27:AB27) & " }" -> { weave } | E27: First(<weave_def>) | F27: weave
A28: 28 | B28: <field_list> | C28: => | D28: ="{ " & TEXTJOIN(", ", TRUE, F28:AB28) & " }" -> { int, long, float, double, char, string, bool, λ } | E28: First(<field_list>) | F28: int | G28: long | H28: float | I28: double | J28: char | K28: string | L28: bool | M28: λ
A29: 29 | B29: <field_dec> | C29: => | D29: ="{ " & TEXTJOIN(", ", TRUE, F29:AB29) & " }" -> { int, long, float, double, char, string, bool } | E29: First(<field_dec>) | F29: int | G29: long | H29: float | I29: double | J29: char | K29: string | L29: bool
A30: 30 | B30: <function> | C30: => | D30: ="{ " & TEXTJOIN(", ", TRUE, F30:AB30) & " }" -> { func, λ } | E30: First(<function>) | F30: func | G30: λ
A31: 31 | B31: <function_def> | C31: => | D31: ="{ " & TEXTJOIN(", ", TRUE, F31:AB31) & " }" -> { func } | E31: First(<function_def>) | F31: func
A32: 32 | B32: <ret_type> | C32: => | D32: ="{ " & TEXTJOIN(", ", TRUE, F32:AB32) & " }" -> { int, long, float, double, char, string, bool, void } | E32: First(<ret_type>) | F32: int | G32: long | H32: float | I32: double | J32: char | K32: string | L32: bool | M32: void
A33: 33 | B33: <ret_struct> | C33: => | D33: ="{ " & TEXTJOIN(", ", TRUE, F33:AB33) & " }" -> { [, λ } | E33: First(<ret_struct>) | F33: [ | G33: λ
A34: 34 | B34: <ret_2D> | C34: => | D34: ="{ " & TEXTJOIN(", ", TRUE, F34:AB34) & " }" -> { [, λ } | E34: First(<ret_2D>) | F34: [ | G34: λ
A35: 35 | B35: <param> | C35: => | D35: ="{ " & TEXTJOIN(", ", TRUE, F35:AB35) & " }" -> { int, long, float, double, char, string, bool, λ } | E35: First(<param>) | F35: int | G35: long | H35: float | I35: double | J35: char | K35: string | L35: bool | M35: λ
A36: 36 | B36: <param_tail> | C36: => | D36: ="{ " & TEXTJOIN(", ", TRUE, F36:AB36) & " }" -> { ,, λ } | E36: First(<param_tail>) | F36: , | G36: λ
A37: 37 | B37: <param_struct> | C37: => | D37: ="{ " & TEXTJOIN(", ", TRUE, F37:AB37) & " }" -> { [, λ } | E37: First(<param_struct>) | F37: [ | G37: λ
A38: 38 | B38: <param_2D> | C38: => | D38: ="{ " & TEXTJOIN(", ", TRUE, F38:AB38) & " }" -> { [, λ } | E38: First(<param_2D>) | F38: [ | G38: λ
A39: 39 | B39: <function_body> | C39: => | D39: ="{ " & TEXTJOIN(", ", TRUE, F39:AB39) & " }" -> { using, local, id , abs, len, pow, sqrt, trap, thread, threadln, if, switch, for, while, do, λ } | E39: First(<function_body>) | F39: using | G39: local | H39: id | I39: abs | J39: len | K39: pow | L39: sqrt | M39: trap | N39: thread | O39: threadln | P39: if | Q39: switch | R39: for | S39: while | T39: do | U39: λ
A40: 40 | B40: <using_block> | C40: => | D40: ="{ " & TEXTJOIN(", ", TRUE, F40:AB40) & " }" -> { using, λ } | E40: First(<using_block>) | F40: using | G40: λ
...

Sheet Follow Set Macro
A1: 1 | B1: <program> | C1: => | D1: ="{ " & TEXTJOIN(", ", TRUE, F1:Z1) & " }" -> { } | E1: Follow(<program>)
A2: 2 | B2: <global_dec> | C2: => | D2: ="{ " & TEXTJOIN(", ", TRUE, F2:Z2) & " }" -> { func, int } | E2: Follow(<global_dec>) | F2: func | G2: int
A3: 3 | B3: <mutability> | C3: => | D3: ="{ " & TEXTJOIN(", ", TRUE, F3:Z3) & " }" -> { ; } | E3: Follow(<mutability>) | F3: ;
A4: 4 | B4: <var_or_weave> | C4: => | D4: ="{ " & TEXTJOIN(", ", TRUE, F4:Z4) & " }" -> { ; } | E4: Follow(<var_or_weave>) | F4: ;
A5: 5 | B5: <const_weave> | C5: => | D5: ="{ " & TEXTJOIN(", ", TRUE, F5:Z5) & " }" -> { ; } | E5: Follow(<const_weave>) | F5: ;
A6: 6 | B6: <dtype> | C6: => | D6: ="{ " & TEXTJOIN(", ", TRUE, F6:Z6) & " }" -> { id, [, ) } | E6: Follow(<dtype>) | F6: id | G6: [ | H6: )
A7: 7 | B7: <var_or_arr> | C7: => | D7: ="{ " & TEXTJOIN(", ", TRUE, F7:Z7) & " }" -> { ; } | E7: Follow(<var_or_arr>) | F7: ;
A8: 8 | B8: <const_or_arr> | C8: => | D8: ="{ " & TEXTJOIN(", ", TRUE, F8:Z8) & " }" -> { ; } | E8: Follow(<const_or_arr>) | F8: ;
A9: 9 | B9: <value> | C9: => | D9: ="{ " & TEXTJOIN(", ", TRUE, F9:Z9) & " }" -> { ,, ;, ) } | E9: Follow(<value>) | F9: , | G9: ; | H9: )
A10: 10 | B10: <multi_dec> | C10: => | D10: ="{ " & TEXTJOIN(", ", TRUE, F10:Z10) & " }" -> { ; } | E10: Follow(<multi_dec>) | F10: ;
A11: 11 | B11: <multi_dec_const> | C11: => | D11: ="{ " & TEXTJOIN(", ", TRUE, F11:Z11) & " }" -> { ; } | E11: Follow(<multi_dec_const>) | F11: ;
A12: 12 | B12: <size> | C12: => | D12: ="{ " & TEXTJOIN(", ", TRUE, F12:Z12) & " }" -> { ] } | E12: Follow(<size>) | F12: ]
A13: 13 | B13: <literals_num> | C13: => | D13: ="{ " & TEXTJOIN(", ", TRUE, F13:Z13) & " }" -> { ,, ;, } } | E13: Follow(<literals_num>) | F13: , | G13: ; | H13: }
A14: 14 | B14: <num_lit> | C14: => | D14: ="{ " & TEXTJOIN(", ", TRUE, F14:Z14) & " }" -> { ,, ;, } } | E14: Follow(<num_lit>) | F14: , | G14: ; | H14: }
A15: 15 | B15: <var_1D_or_2D> | C15: => | D15: ="{ " & TEXTJOIN(", ", TRUE, F15:Z15) & " }" -> { ; } | E15: Follow(<var_1D_or_2D>) | F15: ;
A16: 16 | B16: <1D_elem_list> | C16: => | D16: ="{ " & TEXTJOIN(", ", TRUE, F16:Z16) & " }" -> { } } | E16: Follow(<1D_elem_list>) | F16: }
A17: 17 | B17: <elem_value> | C17: => | D17: ="{ " & TEXTJOIN(", ", TRUE, F17:Z17) & " }" -> { ,, } } | E17: Follow(<elem_value>) | F17: , | G17: }
A18: 18 | B18: <1D_elem_list_tail> | C18: => | D18: ="{ " & TEXTJOIN(", ", TRUE, F18:Z18) & " }" -> { } } | E18: Follow(<1D_elem_list_tail>) | F18: }
A19: 19 | B19: <arr_2D_init_opt> | C19: => | D19: ="{ " & TEXTJOIN(", ", TRUE, F19:Z19) & " }" -> { ; } | E19: Follow(<arr_2D_init_opt>) | F19: ;
A20: 20 | B20: <arr_2D_init> | C20: => | D20: ="{ " & TEXTJOIN(", ", TRUE, F20:Z20) & " }" -> { ; } | E20: Follow(<arr_2D_init>) | F20: ;
A21: 21 | B21: <2D_elem_list> | C21: => | D21: ="{ " & TEXTJOIN(", ", TRUE, F21:Z21) & " }" -> { } } | E21: Follow(<2D_elem_list>) | F21: }
A22: 22 | B22: <2D_elem_list_cont> | C22: => | D22: ="{ " & TEXTJOIN(", ", TRUE, F22:Z22) & " }" -> { } } | E22: Follow(<2D_elem_list_cont>) | F22: }
A23: 23 | B23: <const_1D_or_2D> | C23: => | D23: ="{ " & TEXTJOIN(", ", TRUE, F23:Z23) & " }" -> { ; } | E23: Follow(<const_1D_or_2D>) | F23: ;
A24: 24 | B24: <weave_init_list> | C24: => | D24: ="{ " & TEXTJOIN(", ", TRUE, F24:Z24) & " }" -> { } } | E24: Follow(<weave_init_list>) | F24: }
A25: 25 | B25: <weave_elem> | C25: => | D25: ="{ " & TEXTJOIN(", ", TRUE, F25:Z25) & " }" -> { ,, } } | E25: Follow(<weave_elem>) | F25: , | G25: }
A26: 26 | B26: <weave_init_list_tail> | C26: => | D26: ="{ " & TEXTJOIN(", ", TRUE, F26:Z26) & " }" -> { } } | E26: Follow(<weave_init_list_tail>) | F26: }
A27: 27 | B27: <weave_def> | C27: => | D27: ="{ " & TEXTJOIN(", ", TRUE, F27:Z27) & " }" -> { global , weave, func, int } | E27: Follow(<weave_def>) | F27: global | G27: weave | H27: func | I27: int
A28: 28 | B28: <field_list> | C28: => | D28: ="{ " & TEXTJOIN(", ", TRUE, F28:Z28) & " }" -> { } } | E28: Follow(<field_list>) | F28: }
A29: 29 | B29: <field_dec> | C29: => | D29: ="{ " & TEXTJOIN(", ", TRUE, F29:Z29) & " }" -> { int, long, float, double, char, string, bool, } } | E29: Follow(<field_dec>) | F29: int | G29: long | H29: float | I29: double | J29: char | K29: string | L29: bool | M29: }
A30: 30 | B30: <function> | C30: => | D30: ="{ " & TEXTJOIN(", ", TRUE, F30:Z30) & " }" -> { int } | E30: Follow(<function>) | F30: int
A31: 31 | B31: <function_def> | C31: => | D31: ="{ " & TEXTJOIN(", ", TRUE, F31:Z31) & " }" -> { func, int } | E31: Follow(<function_def>) | F31: func | G31: int
A32: 32 | B32: <ret_type> | C32: => | D32: ="{ " & TEXTJOIN(", ", TRUE, F32:Z32) & " }" -> { func, int } | E32: Follow(<ret_type>) | F32: func | G32: int
A33: 33 | B33: <ret_struct> | C33: => | D33: ="{ " & TEXTJOIN(", ", TRUE, F33:Z33) & " }" -> { id } | E33: Follow(<ret_struct>) | F33: id
A34: 34 | B34: <ret_2D> | C34: => | D34: ="{ " & TEXTJOIN(", ", TRUE, F34:Z34) & " }" -> { id } | E34: Follow(<ret_2D>) | F34: id
A35: 35 | B35: <param> | C35: => | D35: ="{ " & TEXTJOIN(", ", TRUE, F35:Z35) & " }" -> { ) } | E35: Follow(<param>) | F35: )
A36: 36 | B36: <param_tail> | C36: => | D36: ="{ " & TEXTJOIN(", ", TRUE, F36:Z36) & " }" -> { ) } | E36: Follow(<param_tail>) | F36: )
A37: 37 | B37: <param_struct> | C37: => | D37: ="{ " & TEXTJOIN(", ", TRUE, F37:Z37) & " }" -> { ,, ) } | E37: Follow(<param_struct>) | F37: , | G37: )
A38: 38 | B38: <param_2D> | C38: => | D38: ="{ " & TEXTJOIN(", ", TRUE, F38:Z38) & " }" -> { ,, ) } | E38: Follow(<param_2D>) | F38: , | G38: )
A39: 39 | B39: <function_body> | C39: => | D39: ="{ " & TEXTJOIN(", ", TRUE, F39:Z39) & " }" -> { return } | E39: Follow(<function_body>) | F39: return
A40: 40 | B40: <using_block> | C40: => | D40: ="{ " & TEXTJOIN(", ", TRUE, F40:Z40) & " }" -> { local, id , abs, len, pow, sqrt, trap, thread, threadln, if, switch, for, while, do, return } | E40: Follow(<using_block>) | F40: local | G40: id | H40: abs | I40: len | J40: pow | K40: sqrt | L40: trap | M40: thread | N40: threadln | O40: if | P40: switch | Q40: for | R40: while | S40: do | T40: return
...

Sheet Predict Set Macro
A1: 1 | B1: First(<global_dec> <function> <main_func>) = | C1: First(<global_dec>) = | D1: { global, weave, func, int }
A2: 2 | B2: First(global <mutability> ; <global_dec>) = | D2: { global }
A3: 3 | B3: First(<weave_def> <global_dec>) = | C3: First(<weave_def>) = | D3: { weave }
A4: 4 | B4: First(λ - λ) ∪ Follow(<global_dec>) = | C4: Follow(<global_dec>) = | D4: { func, int }
A5: 5 | B5: First(var <var_or_weave>) = | D5: { var }
A6: 6 | B6: First(const <const_weave>) = | D6: { const }
A7: 7 | B7: First(<dtype> id <var_or_arr>) = | C7: First(<dtype>) = | D7: { int, long, float, double, char, string, bool }
A8: 8 | B8: First(id id = { <weave_init_list> }) = | D8: { id }
A9: 9 | B9: First(<dtype> id <const_or_arr>) = | C9: First(<dtype>) = | D9: { int, long, float, double, char, string, bool }
A10: 10 | B10: First(id id = { <weave_init_list> }) = | D10: { id }
A11: 11 | B11: First(int) = | D11: { int }
A12: 12 | B12: First(long) = | D12: { long }
A13: 13 | B13: First(float) = | D13: { float }
A14: 14 | B14: First(double) = | D14: { double }
A15: 15 | B15: First(char) = | D15: { char }
A16: 16 | B16: First(string) = | D16: { string }
A17: 17 | B17: First(bool) = | D17: { bool }
A18: 18 | B18: First(= <value> <multi_dec>) = | D18: { = }
A19: 19 | B19: First([ <size> ] <var_1D_or_2D>) = | D19: { [ }
A20: 20 | B20: First(= <literals_num> <multi_dec_const>) = | D20: { = }
A21: 21 | B21: First([ <size> ] <const_1D_or_2D>) = | D21: { [ }
A22: 22 | B22: First(<string_or_logical_expr>) = | C22: First(<string_or_logical_expr>) = | D22: { !, -, (, id, intlit, longlit, floatlit, doublelit, charlit, stringlit, true, false, abs, len, pow, sqrt }
A23: 23 | B23: First(, id = <value> <multi_dec>) = | D23: { , }
A24: 24 | B24: First(λ - λ) ∪ Follow(<multi_dec>) = | C24: Follow(<multi_dec>) = | D24: { ; }
A25: 25 | B25: First(, id = <literals_num> <multi_dec_const>) = | D25: { , }
A26: 26 | B26: First(λ - λ) ∪ Follow(<multi_dec_const>) = | C26: Follow(<multi_dec_const>) = | D26: { ; }
A27: 27 | B27: First(intlit) = | D27: { intlit }
A28: 28 | B28: First(id) = | D28: { id }
A29: 29 | B29: First(<literals>) = | C29: First(<literals>) = | D29: { intlit, longlit, floatlit, doublelit, charlit, stringlit, true, false }
A30: 30 | B30: First(- <num_lit>) = | D30: { - }
A31: 31 | B31: First(intlit) = | D31: { intlit }
A32: 32 | B32: First(longlit) = | D32: { longlit }
A33: 33 | B33: First(floatlit) = | D33: { floatlit }
A34: 34 | B34: First(doublelit) = | D34: { doublelit }
A35: 35 | B35: First(= { <1D_elem_list> }) = | D35: { = }
A36: 36 | B36: First([ <size> ] <arr_2D_init_opt>) = | D36: { [ }
A37: 37 | B37: First(λ - λ) ∪ Follow(<var_1D_or_2D>) = | C37: Follow(<var_1D_or_2D>) = | D37: { ; }
A38: 38 | B38: First(<elem_value> <1D_elem_list_tail>) = | C38: First(<elem_value>) = | D38: { id, intlit, longlit, floatlit, doublelit, charlit, stringlit, true, false }
A39: 39 | B39: First(<literals>) = | C39: First(<literals>) = | D39: { intlit, longlit, floatlit, doublelit, charlit, stringlit, true, false }
A40: 40 | B40: First(id) = | D40: { id }
...

Sheet predict_set
A1: <program> | B1: { global, weave, func, int }
A2: <global_dec> | B2: { global }
A3: <global_dec> | B3: { weave }
A4: <global_dec> | B4: { func, int }
A5: <mutability> | B5: { var }
A6: <mutability> | B6: { const }
A7: <var_or_weave> | B7: { int, long, float, double, char, string, bool }
A8: <var_or_weave> | B8: { id }
A9: <const_weave> | B9: { int, long, float, double, char, string, bool }
A10: <const_weave> | B10: { id }
A11: <dtype> | B11: { int }
A12: <dtype> | B12: { long }
... A250: <main_body> | B250: { using, local, id, abs, len, pow, sqrt, trap, thread, threadln, if, switch, for, while, do, return }

Sheet Draft
A1: =ROW() -> 1 | B1: <program> | C1: ="=>" -> => | D1: <global_decl> | E1: <recipe_decl> | F1: start | G1: ( | H1: ) | I1: <platter>
A2: =ROW() -> 2 | B2: <global_decl> | C2: ="=>" -> => | D2: piece | E2: <piece_decl> | F2: <global_decl>
A3: =ROW() -> 3 | B3: <global_decl> | C3: ="=>" -> => | D3: chars | E3: <chars_decl> | F3: <global_decl>
A4: =ROW() -> 4 | B4: <global_decl> | C4: ="=>" -> => | D4: sip | E4: <sip_decl> | F4: <global_decl>
A5: =ROW() -> 5 | B5: <global_decl> | C5: ="=>" -> => | D5: flag | E5: <flag_decl> | F5: <global_decl>
A6: =ROW() -> 6 | B6: <global_decl> | C6: ="=>" -> => | D6: <table_prototype> | E6: <global_decl>
A7: =ROW() -> 7 | B7: <global_decl> | C7: ="=>" -> => | D7: id | E7: <table_decl> | F7: <global_decl>
A8: =ROW() -> 8 | B8: <global_decl> | C8: ="=>" -> => | D8: λ
A9: =ROW() -> 9 | B9: <piece_decl> | C9: ="=>" -> => | D9: of | E9: <piece_id> | F9: ;
A10: =ROW() -> 10 | B10: <piece_decl> | C10: ="=>" -> => | D10: <decl_type>
A11: =ROW() -> 11 | B11: <piece_id> | C11: ="=>" -> => | D11: id | E11: <piece_ingredient_init> | F11: <piece_id_tail>
A12: =ROW() -> 12 | B12: <piece_ingredient_init> | C12: ="=>" -> => | D12: ="=" -> = | E12: <strict_piece_expr>
A13: =ROW() -> 13 | B13: <piece_ingredient_init> | C13: ="=>" -> => | D13: λ
A14: =ROW() -> 14 | B14: <strict_piece_expr> | C14: ="=>" -> => | D14: <strict_piece_term> | E14: <strict_piece_add_tail>
A15: =ROW() -> 15 | B15: <strict_piece_term> | C15: ="=>" -> => | D15: <strict_piece_factor> | E15: <strict_piece_mult_tail>
A16: =ROW() -> 16 | B16: <strict_piece_factor> | C16: ="=>" -> => | D16: <ret_piece>
A17: =ROW() -> 17 | B17: <strict_piece_factor> | C17: ="=>" -> => | D17: <id>
A18: =ROW() -> 18 | B18: <strict_piece_factor> | C18: ="=>" -> => | D18: ( | E18: <strict_piece_expr> | F18: )
A19: =ROW() -> 19 | B19: <ret_piece> | C19: ="=>" -> => | D19: topiece | E19: ( | F19: <any_expr> | G19: )
A20: =ROW() -> 20 | B20: <ret_piece> | C20: ="=>" -> => | D20: size | E20: ( | F20: <strict_array_expr> | G20: )
A21: =ROW() -> 21 | B21: <ret_piece> | C21: ="=>" -> => | D21: search | E21: ( | F21: <strict_array_expr> | G21: , | H21: <value> | I21: )
A22: =ROW() -> 22 | B22: <ret_piece> | C22: ="=>" -> => | D22: fact | E22: ( | F22: <strict_piece_expr> | G22: )
A23: =ROW() -> 23 | B23: <ret_piece> | C23: ="=>" -> => | D23: pow | E23: ( | F23: <strict_piece_expr> | G23: , | H23: <strict_piece_expr> | I23: )
A24: =ROW() -> 24 | B24: <ret_piece> | C24: ="=>" -> => | D24: piece_lit
A25: =ROW() -> 25 | B25: <any_expr> | C25: ="=>" -> => | D25: <ret_piece> | E25: <piece_mult_tail> | F25: <piece_add_tail> | G25: <piece_rel_gate>
A26: =ROW() -> 26 | B26: <any_expr> | C26: ="=>" -> => | D26: <ret_sip> | E26: <sip_mult_tail> | F26: <sip_add_tail> | G26: <sip_rel_gate>
A27: =ROW() -> 27 | B27: <any_expr> | C27: ="=>" -> => | D27: <ret_chars> | E27: <chars_add_tail> | F27: <chars_rel_gate>
A28: =ROW() -> 28 | B28: <any_expr> | C28: ="=>" -> => | D28: <ret_flag> | E28: <flag_logic_tail>
A29: =ROW() -> 29 | B29: <any_expr> | C29: ="=>" -> => | D29: <id> | E29: <univ_mult_tail> | F29: <univ_add_tail> | G29: <univ_rel_gate>
A30: =ROW() -> 30 | B30: <any_expr> | C30: ="=>" -> => | D30: ( | E30: <paren_dispatch>
A31: =ROW() -> 31 | B31: <any_expr> | C31: ="=>" -> => | D31: not | E31: <must_be_flag>
A32: =ROW() -> 32 | B32: <piece_mult_tail> | C32: ="=>" -> => | D32: * | E32: <piece_factor> | F32: <piece_mult_tail>
A33: =ROW() -> 33 | B33: <piece_mult_tail> | C33: ="=>" -> => | D33: / | E33: <piece_factor> | F33: <piece_mult_tail>
A34: =ROW() -> 34 | B34: <piece_mult_tail> | C34: ="=>" -> => | D34: % | E34: <piece_factor> | F34: <piece_mult_tail>
A35: =ROW() -> 35 | B35: <piece_mult_tail> | C35: ="=>" -> => | D35: λ
A36: =ROW() -> 36 | B36: <piece_factor> | C36: ="=>" -> => | D36: <ret_piece>
A37: =ROW() -> 37 | B37: <piece_factor> | C37: ="=>" -> => | D37: <id>
A38: =ROW() -> 38 | B38: <piece_factor> | C38: ="=>" -> => | D38: ( | E38: <piece_inner_dispatch>
A39: =ROW() -> 39 | B39: <id> | C39: ="=>" -> => | D39: id | E39: <id_tail>
A40: =ROW() -> 40 | B40: <id> | C40: ="=>" -> => | D40: <ret_array> | E40: <array_accessor>
...

Sheet RAph
A1: =ROW() -> 1 | B1: <program> | C1: ="=>" -> => | D1: <global_decl> | E1: <recipe_decl> | F1: <start_recipe>
A2: =ROW() -> 2 | B2: <global_decl> | C2: ="=>" -> => | D2: <ingredient_decl> | E2: <global_decl>
A3: =ROW() -> 3 | B3: <global_decl> | C3: ="=>" -> => | D3: <array_declaration> | E3: <global_decl>
A4: =ROW() -> 4 | B4: <global_decl> | C4: ="=>" -> => | D4: <table_prototype> | E4: <global_decl>
A5: =ROW() -> 5 | B5: <global_decl> | C5: ="=>" -> => | D5: <table_declaration> | E5: <global_decl>
A6: =ROW() -> 6 | B6: <global_decl> | C6: ="=>" -> => | D6: λ
A7: =ROW() -> 7 | B7: <ingredient_decl> | C7: ="=>" -> => | D7: <data_type> | E7: of | F7: <ingredient_id> | G7: ; | H7: <ingredient_decl>
A8: =ROW() -> 8 | B8: <ingredient_decl> | C8: ="=>" -> => | D8: λ
A9: =ROW() -> 9 | B9: <data_type> | C9: ="=>" -> => | D9: piece
A10: =ROW() -> 10 | B10: <data_type> | C10: ="=>" -> => | D10: sip
A11: =ROW() -> 11 | B11: <data_type> | C11: ="=>" -> => | D11: flag
A12: =ROW() -> 12 | B12: <data_type> | C12: ="=>" -> => | D12: chars
A13: =ROW() -> 13 | B13: <ingredient_id> | C13: ="=>" -> => | D13: id | E13: <ingredient_init> | F13: <ingredient_id_tail>
A14: =ROW() -> 14 | B14: <ingredient_init> | C14: ="=>" -> => | D14: ="=" -> = | E14: <expr>
A15: =ROW() -> 15 | B15: <ingredient_init> | C15: ="=>" -> => | D15: λ
A16: =ROW() -> 16 | B16: <ingredient_id_tail> | C16: ="=>" -> => | D16: , | E16: id | F16: <ingredient_init> | G16: <ingredient_id_tail>
A17: =ROW() -> 17 | B17: <ingredient_id_tail> | C17: ="=>" -> => | D17: λ
A18: =ROW() -> 18 | B18: <expr> | C18: ="=>" -> => | D18: <or_expr>
A19: =ROW() -> 19 | B19: <or_expr> | C19: => | D19: <and_expr> | E19: <or_tail>
A20: =ROW() -> 20 | B20: <and_expr> | C20: ="=>" -> => | D20: <eq_expr> | E20: <and_tail>
A21: =ROW() -> 21 | B21: <or_tail> | C21: ="=>" -> => | D21: or | E21: <and_expr> | F21: <or_tail>
A22: =ROW() -> 22 | B22: <or_tail> | C22: ="=>" -> => | D22: λ
A23: =ROW() -> 23 | B23: <eq_expr> | C23: ="=>" -> => | D23: <rel_expr> | E23: <eq_tail>
A24: =ROW() -> 24 | B24: <and_tail> | C24: ="=>" -> => | D24: and | E24: <eq_expr> | F24: <and_tail>
A25: =ROW() -> 25 | B25: <and_tail> | C25: ="=>" -> => | D25: λ
A26: =ROW() -> 26 | B26: <rel_expr> | C26: ="=>" -> => | D26: <add_expr> | E26: <rel_tail>
A27: =ROW() -> 27 | B27: <eq_tail> | C27: ="=>" -> => | D27: == | E27: <rel_expr> | F27: <eq_tail>
A28: =ROW() -> 28 | B28: <eq_tail> | C28: ="=>" -> => | D28: != | E28: <rel_expr> | F28: <eq_tail>
A29: =ROW() -> 29 | B29: <eq_tail> | C29: ="=>" -> => | D29: λ
A30: =ROW() -> 30 | B30: <add_expr> | C30: ="=>" -> => | D30: <mult_expr> | E30: <add_tail>
A31: =ROW() -> 31 | B31: <rel_tail> | C31: ="=>" -> => | D31: > | E31: <add_expr> | F31: <rel_tail>
A32: =ROW() -> 32 | B32: <rel_tail> | C32: ="=>" -> => | D32: < | E32: <add_expr> | F32: <rel_tail>
A33: =ROW() -> 33 | B33: <rel_tail> | C33: ="=>" -> => | D33: >= | E33: <add_expr> | F33: <rel_tail>
A34: =ROW() -> 34 | B34: <rel_tail> | C34: ="=>" -> => | D34: <= | E34: <add_expr> | F34: <rel_tail>
A35: =ROW() -> 35 | B35: <rel_tail> | C35: ="=>" -> => | D35: λ
A36: =ROW() -> 36 | B36: <mult_expr> | C36: ="=>" -> => | D36: <unary_expr> | E36: <mult_tail>
A37: =ROW() -> 37 | B37: <add_tail> | C37: ="=>" -> => | D37: + | E37: <mult_expr> | F37: <add_tail>
A38: =ROW() -> 38 | B38: <add_tail> | C38: ="=>" -> => | D38: - | E38: <mult_expr> | F38: <add_tail>
A39: =ROW() -> 39 | B39: <add_tail> | C39: ="=>" -> => | D39: λ
A40: =ROW() -> 40 | B40: <unary_expr> | C40: ="=>" -> => | D40: not | E40: <unary_expr>
...

Sheet CFG (Old)
A1: =ROW() -> 1 | B1: <program> | C1: ="=>" -> => | D1: <global_decl> | E1: <recipe_decl> | F1: start | G1: ( | H1: ) | I1: <platter>
A2: =ROW() -> 2 | B2: <global_decl> | C2: ="=>" -> => | D2: <decl_data_type> | E2: <global_decl>
A3: =ROW() -> 3 | B3: <global_decl> | C3: ="=>" -> => | D3: <table_prototype> | E3: <global_decl>
A4: =ROW() -> 4 | B4: <global_decl> | C4: ="=>" -> => | D4: id | E4: <table_decl> | F4: <global_decl>
A5: =ROW() -> 5 | B5: <global_decl> | C5: ="=>" -> => | D5: λ
A6: =ROW() -> 6 | B6: <decl_data_type> | C6: ="=>" -> => | D6: piece | E6: <decl_type>
A7: =ROW() -> 7 | B7: <decl_data_type> | C7: ="=>" -> => | D7: sip | E7: <decl_type>
A8: =ROW() -> 8 | B8: <decl_data_type> | C8: ="=>" -> => | D8: flag | E8: <decl_type>
A9: =ROW() -> 9 | B9: <decl_data_type> | C9: ="=>" -> => | D9: chars | E9: <decl_type>
A10: =ROW() -> 10 | B10: <decl_type> | C10: ="=>" -> => | D10: of | E10: <ingredient_id> | F10: ;
A11: =ROW() -> 11 | B11: <decl_type> | C11: ="=>" -> => | D11: <dimensions> | E11: of | F11: <array_declare> | G11: ;
A12: =ROW() -> 12 | B12: <ingredient_id> | C12: ="=>" -> => | D12: id | E12: <ingredient_init> | F12: <ingredient_id_tail>
A13: =ROW() -> 13 | B13: <ingredient_init> | C13: ="=>" -> => | D13: ="=" -> = | E13: <expr>
A14: =ROW() -> 14 | B14: <ingredient_init> | C14: ="=>" -> => | D14: λ
A15: =ROW() -> 15 | B15: <ingredient_id_tail> | C15: ="=>" -> => | D15: , | E15: id | F15: <ingredient_init> | G15: <ingredient_id_tail>
A16: =ROW() -> 16 | B16: <ingredient_id_tail> | C16: ="=>" -> => | D16: λ
A17: =ROW() -> 17 | B17: <expr> | C17: ="=>" -> => | D17: <or_expr>
A18: =ROW() -> 18 | B18: <or_expr> | C18: ="=>" -> => | D18: <and_expr> | E18: <or_tail>
A19: =ROW() -> 19 | B19: <and_expr> | C19: ="=>" -> => | D19: <eq_expr> | E19: <and_tail>
A20: =ROW() -> 20 | B20: <or_tail> | C20: ="=>" -> => | D20: or | E20: <and_expr> | F20: <or_tail>
A21: =ROW() -> 21 | B21: <or_tail> | C21: ="=>" -> => | D21: λ
A22: =ROW() -> 22 | B22: <eq_expr> | C22: ="=>" -> => | D22: <rel_expr> | E22: <eq_tail>
A23: =ROW() -> 23 | B23: <and_tail> | C23: ="=>" -> => | D23: and | E23: <eq_expr> | F23: <and_tail>
A24: =ROW() -> 24 | B24: <and_tail> | C24: ="=>" -> => | D24: λ
A25: =ROW() -> 25 | B25: <rel_expr> | C25: ="=>" -> => | D25: <add_expr> | E25: <rel_tail>
A26: =ROW() -> 26 | B26: <eq_tail> | C26: ="=>" -> => | D26: == | E26: <rel_expr> | F26: <eq_tail>
A27: =ROW() -> 27 | B27: <eq_tail> | C27: ="=>" -> => | D27: != | E27: <rel_expr> | F27: <eq_tail>
A28: =ROW() -> 28 | B28: <eq_tail> | C28: ="=>" -> => | D28: λ
A29: =ROW() -> 29 | B29: <add_expr> | C29: ="=>" -> => | D29: <mult_expr> | E29: <add_tail>
A30: =ROW() -> 30 | B30: <rel_tail> | C30: ="=>" -> => | D30: > | E30: <add_expr> | F30: <rel_tail>
A31: =ROW() -> 31 | B31: <rel_tail> | C31: ="=>" -> => | D31: < | E31: <add_expr> | F31: <rel_tail>
A32: =ROW() -> 32 | B32: <rel_tail> | C32: ="=>" -> => | D32: >= | E32: <add_expr> | F32: <rel_tail>
A33: =ROW() -> 33 | B33: <rel_tail> | C33: ="=>" -> => | D33: <= | E33: <add_expr> | F33: <rel_tail>
A34: =ROW() -> 34 | B34: <rel_tail> | C34: ="=>" -> => | D34: λ
A35: =ROW() -> 35 | B35: <mult_expr> | C35: ="=>" -> => | D35: <unary_expr> | E35: <mult_tail>
A36: =ROW() -> 36 | B36: <add_tail> | C36: ="=>" -> => | D36: + | E36: <mult_expr> | F36: <add_tail>
A37: =ROW() -> 37 | B37: <add_tail> | C37: ="=>" -> => | D37: - | E37: <mult_expr> | F37: <add_tail>
A38: =ROW() -> 38 | B38: <add_tail> | C38: ="=>" -> => | D38: λ
A39: =ROW() -> 39 | B39: <unary_expr> | C39: ="=>" -> => | D39: not | E39: <unary_expr>
A40: =ROW() -> 40 | B40: <unary_expr> | C40: ="=>" -> => | D40: <primary_val>
...

Sheet Raph - CFG
A1: =ROW() -> 1 | B1: <program> | C1: ="=>" -> => | D1: <global_decl> | E1: <recipe_decl> | F1: start | G1: ( | H1: ) | I1: <platter>
A2: =ROW() -> 2 | B2: <global_decl> | C2: ="=>" -> => | D2: piece | E2: <piece_decl> | F2: <global_decl>
A3: =ROW() -> 3 | B3: <global_decl> | C3: ="=>" -> => | D3: chars | E3: <chars_decl> | F3: <global_decl>
A4: =ROW() -> 4 | B4: <global_decl> | C4: ="=>" -> => | D4: sip | E4: <sip_decl> | F4: <global_decl>
A5: =ROW() -> 5 | B5: <global_decl> | C5: ="=>" -> => | D5: flag | E5: <flag_decl> | F5: <global_decl>
A6: =ROW() -> 6 | B6: <global_decl> | C6: ="=>" -> => | D6: <table_prototype> | E6: <global_decl>
A7: =ROW() -> 7 | B7: <global_decl> | C7: ="=>" -> => | D7: id | E7: <table_decl> | F7: <global_decl>
A8: =ROW() -> 8 | B8: <global_decl> | C8: ="=>" -> => | D8: λ
A9: =ROW() -> 9 | B9: <piece_decl> | C9: ="=>" -> => | D9: of | E9: <piece_id> | F9: ;
A10: =ROW() -> 10 | B10: <piece_decl> | C10: ="=>" -> => | D10: <decl_type>
A11: =ROW() -> 11 | B11: <piece_id> | C11: ="=>" -> => | D11: id | E11: <piece_ingredient_init> | F11: <piece_id_tail>
A12: =ROW() -> 12 | B12: <piece_ingredient_init> | C12: ="=>" -> => | D12: ="=" -> = | E12: <strict_piece_expr>
A13: =ROW() -> 13 | B13: <piece_ingredient_init> | C13: ="=>" -> => | D13: λ
A14: =ROW() -> 14 | B14: <piece_id_tail> | D14: , | E14: id | F14: <piece_ingredient_init> | G14: <piece_id_tail>
A15: =ROW() -> 15 | B15: <piece_id_tail> | D15: λ
A16: =ROW() -> 16 | B16: <chars_decl> | C16: ="=>" -> => | D16: of | E16: <chars_id> | F16: ;
A17: =ROW() -> 17 | B17: <chars_decl> | C17: ="=>" -> => | D17: <decl_type>
A18: =ROW() -> 18 | B18: <chars_id> | C18: ="=>" -> => | D18: id | E18: <chars_ingredient_init> | F18: <chars_id_tail>
A19: =ROW() -> 19 | B19: <chars_ingredient_init> | C19: ="=>" -> => | D19: ="=" -> = | E19: <strict_chars_expr>
A20: =ROW() -> 20 | B20: <chars_ingredient_init> | C20: ="=>" -> => | D20: λ
A21: =ROW() -> 21 | B21: <chars_id_tail> | D21: , | E21: id | F21: <chars_ingredient_init> | G21: <chars_id_tail>
A22: =ROW() -> 22 | B22: <chars_id_tail> | D22: λ
A23: =ROW() -> 23 | B23: <sip_decl> | C23: ="=>" -> => | D23: of | E23: <sip_id> | F23: ;
A24: =ROW() -> 24 | B24: <sip_decl> | C24: ="=>" -> => | D24: <decl_type>
A25: =ROW() -> 25 | B25: <sip_id> | C25: ="=>" -> => | D25: id | E25: <sip_ingredient_init> | F25: <sip_id_tail>
A26: =ROW() -> 26 | B26: <sip_ingredient_init> | C26: ="=>" -> => | D26: ="=" -> = | E26: <strict_sip_expr>
A27: =ROW() -> 27 | B27: <sip_ingredient_init> | C27: ="=>" -> => | D27: λ
A28: =ROW() -> 28 | B28: <sip_id_tail> | D28: , | E28: id | F28: <sip_ingredient_init> | G28: <sip_id_tail>
A29: =ROW() -> 29 | B29: <sip_id_tail> | D29: λ
A30: =ROW() -> 30 | B30: <flag_decl> | C30: ="=>" -> => | D30: of | E30: <flag_id> | F30: ;
A31: =ROW() -> 31 | B31: <flag_decl> | C31: ="=>" -> => | D31: <decl_type>
A32: =ROW() -> 32 | B32: <flag_id> | C32: ="=>" -> => | D32: id | E32: <flag_ingredient_init> | F32: <flag_id_tail>
A33: =ROW() -> 33 | B33: <flag_ingredient_init> | C33: ="=>" -> => | D33: ="=" -> = | E33: <strict_flag_expr>
A34: =ROW() -> 34 | B34: <flag_ingredient_init> | C34: ="=>" -> => | D34: λ
A35: =ROW() -> 35 | B35: <flag_id_tail> | D35: , | E35: id | F35: <flag_ingredient_init> | G35: <flag_id_tail>
A36: =ROW() -> 36 | B36: <flag_id_tail> | D36: λ
A37: =ROW() -> 37 | B37: <table_decl> | C37: ="=>" -> => | D37: of | E37: <table_declare> | F37: ;
A38: =ROW() -> 38 | B38: <table_decl> | C38: ="=>" -> => | D38: <decl_type>
A39: =ROW() -> 39 | B39: <decl_type> | C39: ="=>" -> => | D39: <dimensions> | E39: of | F39: <array_declare> | G39: ;
A40: =ROW() -> 40 | B40: <id_tail> | C40: ="=>" -> => | D40: <call_tailopt> | E40: <accessor_tail>
...

Sheet Copy of Raph - CFG
A1: =ROW() -> 1 | B1: <program> | C1: ="=>" -> => | D1: <global_decl> | E1: <recipe_decl> | F1: start | G1: ( | H1: ) | I1: <platter>
A2: =ROW() -> 2 | B2: <global_decl> | C2: ="=>" -> => | D2: piece | E2: <piece_decl> | F2: <global_decl>
A3: =ROW() -> 3 | B3: <global_decl> | C3: ="=>" -> => | D3: chars | E3: <chars_decl> | F3: <global_decl>
A4: =ROW() -> 4 | B4: <global_decl> | C4: ="=>" -> => | D4: sip | E4: <sip_decl> | F4: <global_decl>
A5: =ROW() -> 5 | B5: <global_decl> | C5: ="=>" -> => | D5: flag | E5: <flag_decl> | F5: <global_decl>
A6: =ROW() -> 6 | B6: <global_decl> | C6: ="=>" -> => | D6: <table_prototype> | E6: <global_decl>
A7: =ROW() -> 7 | B7: <global_decl> | C7: ="=>" -> => | D7: id | E7: <table_decl> | F7: <global_decl>
A8: =ROW() -> 8 | B8: <global_decl> | C8: ="=>" -> => | D8: λ
A9: =ROW() -> 9 | B9: <piece_decl> | C9: ="=>" -> => | D9: of | E9: <piece_id> | F9: ;
A10: =ROW() -> 10 | B10: <piece_decl> | C10: ="=>" -> => | D10: <decl_type>
A11: =ROW() -> 11 | B11: <piece_id> | C11: ="=>" -> => | D11: id | E11: <piece_ingredient_init> | F11: <piece_id_tail>
A12: =ROW() -> 12 | B12: <piece_ingredient_init> | C12: ="=>" -> => | D12: ="=" -> = | E12: <strict_piece_expr>
A13: =ROW() -> 13 | B13: <piece_ingredient_init> | C13: ="=>" -> => | D13: λ
A14: =ROW() -> 14 | B14: <strict_piece_expr> | C14: => | D14: <strict_piece_term> | E14: <strict_piece_add_tail>
A15: =ROW() -> 15 | B15: <strict_piece_term> | C15: => | D15: <strict_piece_factor> | E15: <strict_piece_mult_tail>
A16: =ROW() -> 16 | B16: <strict_piece_factor> | C16: => | D16: <ret_piece>
A17: =ROW() -> 17 | B17: <strict_piece_factor> | C17: => | D17: <id>
A18: =ROW() -> 18 | B18: <strict_piece_factor> | C18: => | D18: ( | E18: <strict_piece_expr> | F18: )
A19: =ROW() -> 19 | B19: <ret_piece> | C19: => | D19: topiece | E19: ( | F19: <any_expr> | G19: )
A20: =ROW() -> 20 | B20: <ret_piece> | C20: => | D20: size | E20: ( | F20: <strict_array_expr> | G20: )
A21: =ROW() -> 21 | B21: <ret_piece> | C21: => | D21: search | E21: ( | F21: <strict_array_expr> | G21: , | H21: <value> | I21: )
A22: =ROW() -> 22 | B22: <ret_piece> | C22: => | D22: fact | E22: ( | F22: <strict_piece_expr> | G22: )
A23: =ROW() -> 23 | B23: <ret_piece> | C23: => | D23: pow | E23: ( | F23: <strict_piece_expr> | G23: , | H23: <strict_piece_expr> | I23: )
A24: =ROW() -> 24 | B24: <ret_piece> | C24: => | D24: piece_lit
A25: =ROW() -> 25 | B25: <any_expr> | C25: => | D25: <ret_piece> | E25: <piece_mult_tail> | F25: <piece_add_tail> | G25: <piece_rel_gate>
A26: =ROW() -> 26 | B26: <any_expr> | C26: => | D26: <ret_sip> | E26: <sip_mult_tail> | F26: <sip_add_tail> | G26: <sip_rel_gate>
A27: =ROW() -> 27 | B27: <any_expr> | C27: => | D27: <ret_chars> | E27: <chars_add_tail> | F27: <chars_rel_gate>
A28: =ROW() -> 28 | B28: <any_expr> | C28: => | D28: <ret_flag> | E28: <flag_logic_tail>
A29: =ROW() -> 29 | B29: <any_expr> | C29: => | D29: <id> | E29: <univ_mult_tail> | F29: <univ_add_tail> | G29: <univ_rel_gate>
A30: =ROW() -> 30 | B30: <any_expr> | C30: => | D30: ( | E30: <paren_dispatch>
A31: =ROW() -> 31 | B31: <any_expr> | C31: => | D31: not | E31: <must_be_flag>
A32: =ROW() -> 32 | B32: <piece_mult_tail> | C32: => | D32: * | E32: <piece_factor> | F32: <piece_mult_tail>
A33: =ROW() -> 33 | B33: <piece_mult_tail> | C33: => | D33: / | E33: <piece_factor> | F33: <piece_mult_tail>
A34: =ROW() -> 34 | B34: <piece_mult_tail> | C34: => | D34: % | E34: <piece_factor> | F34: <piece_mult_tail>
A35: =ROW() -> 35 | B35: <piece_mult_tail> | C35: => | D35: λ
A36: =ROW() -> 36 | B36: <piece_factor> | C36: => | D36: <ret_piece>
A37: =ROW() -> 37 | B37: <piece_factor> | C37: => | D37: <id>
A38: =ROW() -> 38 | B38: <piece_factor> | C38: => | D38: ( | E38: <piece_inner_dispatch>
A39: =ROW() -> 39 | B39: <id> | C39: => | D39: id | E39: <id_tail>
A40: =ROW() -> 40 | B40: <id_tail> | C40: ="=>" -> => | D40: <call_tailopt> | E40: <accessor_tail>
...

Sheet Predict Set Macro (Old)
A1: =ROW() -> 1 | B1: =IF(CFG!D1 = "λ", ("First(λ - λ) ∪ Follow(" & CFG!B1 & ") ="), ("First(" & TEXTJOIN(" ", TRUE, CFG!D1:AB1) & ") =")) -> #REF! | C1: =IFERROR(__xludf.DUMMYFUNCTION("IF( REGEXMATCH($B1, ""^First\(λ - λ\) ∪ Follow\(""), ""Follow("" & REGEXEXTRACT($B1, ""Follow\(([^)]+)\)"") & "") ="", IF( OR( REGEXMATCH($B1, ""^First\([^<]""), REGEXMATCH($B1, ""^First\(<[^A-Za-z_]"") ), """", IF( "&" CFG!$D1=""λ"", ""Follow("" & CFG!$B1 & "") ="", ""First("" & CFG!$D1 & "") ="" ) ) ) "),"#REF!") -> #REF! | D1: =IFERROR(__xludf.DUMMYFUNCTION("IF( $C1="""", ""{ "" & IF( REGEXMATCH(B1, ""^First\(\)""), "")"", REGEXEXTRACT(B1, ""^First\(([^ )]+)"") ) & "" }"", IF( REGEXMATCH($C1, ""^First\(<""), VLOOKUP(REGEXEXTRACT($C1, ""\(([^)]+)\)""), 'First Set Macro"&"A'!B:D, 3, FALSE), IF( REGEXMATCH($C1, ""^Follow\(<""), VLOOKUP(REGEXEXTRACT($C1, ""\(([^)]+)\)""), 'Follow Set Macros'!B:D, 3, FALSE), ""{ "" & REGEXEXTRACT($C1, ""\(([^)]+)\)"") & "" }"" ) ) ) "),"#REF!") -> #REF!
A2: =ROW() -> 2 | B2: =IF(CFG!D2 = "λ", ("First(λ - λ) ∪ Follow(" & CFG!B2 & ") ="), ("First(" & TEXTJOIN(" ", TRUE, CFG!D2:AB2) & ") =")) -> #REF! | C2: =IFERROR(__xludf.DUMMYFUNCTION("IF( REGEXMATCH(B2, ""^First\(λ - λ\) ∪ Follow\(""), ""Follow("" & REGEXEXTRACT(B2, ""Follow\(([^)]+)\)"") & "") ="", IF( OR( REGEXMATCH(B2, ""^First\([^<]""), REGEXMATCH(B2, ""^First\(<[^A-Za-z_]"") ), """", IF( CFG"&"!D2=""λ"", ""Follow("" & CFG!B2 & "") ="", ""First("" & CFG!D2 & "") ="" ) ) ) "),"#REF!") -> #REF! | D2: =IFERROR(__xludf.DUMMYFUNCTION("IF( $C2="""", ""{ "" & IF( REGEXMATCH(B2, ""^First\(\)""), "")"", REGEXEXTRACT(B2, ""^First\(([^ )]+)"") ) & "" }"", IF( REGEXMATCH($C2, ""^First\(<""), VLOOKUP(REGEXEXTRACT($C2, ""\(([^)]+)\)""), 'First Set Macro"&"A'!B:D, 3, FALSE), IF( REGEXMATCH($C2, ""^Follow\(<""), VLOOKUP(REGEXEXTRACT($C2, ""\(([^)]+)\)""), 'Follow Set Macros'!B:D, 3, FALSE), ""{ "" & REGEXEXTRACT($C2, ""\(([^)]+)\)"") & "" }"" ) ) ) "),"#REF!") -> #REF!
A3: =ROW() -> 3 | B3: =IF(CFG!D3 = "λ", ("First(λ - λ) ∪ Follow(" & CFG!B3 & ") ="), ("First(" & TEXTJOIN(" ", TRUE, CFG!D3:AB3) & ") =")) -> #REF! | C3: =IFERROR(__xludf.DUMMYFUNCTION("IF( REGEXMATCH(B3, ""^First\(λ - λ\) ∪ Follow\(""), ""Follow("" & REGEXEXTRACT(B3, ""Follow\(([^)]+)\)"") & "") ="", IF( OR( REGEXMATCH(B3, ""^First\([^<]""), REGEXMATCH(B3, ""^First\(<[^A-Za-z_]"") ), """", IF( CFG"&"!D3=""λ"", ""Follow("" & CFG!B3 & "") ="", ""First("" & CFG!D3 & "") ="" ) ) ) "),"#REF!") -> #REF! | D3: =IFERROR(__xludf.DUMMYFUNCTION("IF( $C3="""", ""{ "" & IF( REGEXMATCH(B3, ""^First\(\)""), "")"", REGEXEXTRACT(B3, ""^First\(([^ )]+)"") ) & "" }"", IF( REGEXMATCH($C3, ""^First\(<""), VLOOKUP(REGEXEXTRACT($C3, ""\(([^)]+)\)""), 'First Set Macro"&"A'!B:D, 3, FALSE), IF( REGEXMATCH($C3, ""^Follow\(<""), VLOOKUP(REGEXEXTRACT($C3, ""\(([^)]+)\)""), 'Follow Set Macros'!B:D, 3, FALSE), ""{ "" & REGEXEXTRACT($C3, ""\(([^)]+)\)"") & "" }"" ) ) ) "),"#REF!") -> #REF!
A4: =ROW() -> 4 | B4: =IF(CFG!D4 = "λ", ("First(λ - λ) ∪ Follow(" & CFG!B4 & ") ="), ("First(" & TEXTJOIN(" ", TRUE, CFG!D4:AB4) & ") =")) -> #REF! | C4: =IFERROR(__xludf.DUMMYFUNCTION("IF( REGEXMATCH(B4, ""^First\(λ - λ\) ∪ Follow\(""), ""Follow("" & REGEXEXTRACT(B4, ""Follow\(([^)]+)\)"") & "") ="", IF( OR( REGEXMATCH(B4, ""^First\([^<]""), REGEXMATCH(B4, ""^First\(<[^A-Za-z_]"") ), """", IF( CFG"&"!D4=""λ"", ""Follow("" & CFG!B4 & "") ="", ""First("" & CFG!D4 & "") ="" ) ) ) "),"#REF!") -> #REF! | D4: =IFERROR(__xludf.DUMMYFUNCTION("IF( $C4="""", ""{ "" & IF( REGEXMATCH(B4, ""^First\(\)""), "")"", REGEXEXTRACT(B4, ""^First\(([^ )]+)"") ) & "" }"", IF( REGEXMATCH($C4, ""^First\(<""), VLOOKUP(REGEXEXTRACT($C4, ""\(([^)]+)\)""), 'First Set Macro"&"A'!B:D, 3, FALSE), IF( REGEXMATCH($C4, ""^Follow\(<""), VLOOKUP(REGEXEXTRACT($C4, ""\(([^)]+)\)""), 'Follow Set Macros'!B:D, 3, FALSE), ""{ "" & REGEXEXTRACT($C4, ""\(([^)]+)\)"") & "" }"" ) ) ) "),"#REF!") -> #REF!
A5: =ROW() -> 5 | B5: =IF(CFG!D5 = "λ", ("First(λ - λ) ∪ Follow(" & CFG!B5 & ") ="), ("First(" & TEXTJOIN(" ", TRUE, CFG!D5:AB5) & ") =")) -> #REF! | C5: =IFERROR(__xludf.DUMMYFUNCTION("IF( REGEXMATCH(B5, ""^First\(λ - λ\) ∪ Follow\(""), ""Follow("" & REGEXEXTRACT(B5, ""Follow\(([^)]+)\)"") & "") ="", IF( OR( REGEXMATCH(B5, ""^First\([^<]""), REGEXMATCH(B5, ""^First\(<[^A-Za-z_]"") ), """", IF( CFG"&"!D5=""λ"", ""Follow("" & CFG!B5 & "") ="", ""First("" & CFG!D5 & "") ="" ) ) ) "),"#REF!") -> #REF! | D5: =IFERROR(__xludf.DUMMYFUNCTION("IF( $C5="""", ""{ "" & IF( REGEXMATCH(B5, ""^First\(\)""), "")"", REGEXEXTRACT(B5, ""^First\(([^ )]+)"") ) & "" }"", IF( REGEXMATCH($C5, ""^First\(<""), VLOOKUP(REGEXEXTRACT($C5, ""\(([^)]+)\)""), 'First Set Macro"&"A'!B:D, 3, FALSE), IF( REGEXMATCH($C5, ""^Follow\(<""), VLOOKUP(REGEXEXTRACT($C5, ""\(([^)]+)\)""), 'Follow Set Macros'!B:D, 3, FALSE), ""{ "" & REGEXEXTRACT($C5, ""\(([^)]+)\)"") & "" }"" ) ) ) "),"#REF!") -> #REF!
A6: =ROW() -> 6 | B6: =IF(CFG!D6 = "λ", ("First(λ - λ) ∪ Follow(" & CFG!B6 & ") ="), ("First(" & TEXTJOIN(" ", TRUE, CFG!D6:AB6) & ") =")) -> #REF! | C6: =IFERROR(__xludf.DUMMYFUNCTION("IF( REGEXMATCH(B6, ""^First\(λ - λ\) ∪ Follow\(""), ""Follow("" & REGEXEXTRACT(B6, ""Follow\(([^)]+)\)"") & "") ="", IF( OR( REGEXMATCH(B6, ""^First\([^<]""), REGEXMATCH(B6, ""^First\(<[^A-Za-z_]"") ), """", IF( CFG"&"!D6=""λ"", ""Follow("" & CFG!B6 & "") ="", ""First("" & CFG!D6 & "") ="" ) ) ) "),"#REF!") -> #REF! | D6: =IFERROR(__xludf.DUMMYFUNCTION("IF( $C6="""", ""{ "" & IF( REGEXMATCH(B6, ""^First\(\)""), "")"", REGEXEXTRACT(B6, ""^First\(([^ )]+)"") ) & "" }"", IF( REGEXMATCH($C6, ""^First\(<""), VLOOKUP(REGEXEXTRACT($C6, ""\(([^)]+)\)""), 'First Set Macro"&"A'!B:D, 3, FALSE), IF( REGEXMATCH($C6, ""^Follow\(<""), VLOOKUP(REGEXEXTRACT($C6, ""\(([^)]+)\)""), 'Follow Set Macros'!B:D, 3, FALSE), ""{ "" & REGEXEXTRACT($C6, ""\(([^)]+)\)"") & "" }"" ) ) ) "),"#REF!") -> #REF!
A7: =ROW() -> 7 | B7: =IF(CFG!D7 = "λ", ("First(λ - λ) ∪ Follow(" & CFG!B7 & ") ="), ("First(" & TEXTJOIN(" ", TRUE, CFG!D7:AB7) & ") =")) -> #REF! | C7: =IFERROR(__xludf.DUMMYFUNCTION("IF( REGEXMATCH(B7, ""^First\(λ - λ\) ∪ Follow\(""), ""Follow("" & REGEXEXTRACT(B7, ""Follow\(([^)]+)\)"") & "") ="", IF( OR( REGEXMATCH(B7, ""^First\([^<]""), REGEXMATCH(B7, ""^First\(<[^A-Za-z_]"") ), """", IF( CFG"&"!D7=""λ"", ""Follow("" & CFG!B7 & "") ="", ""First("" & CFG!D7 & "") ="" ) ) ) "),"#REF!") -> #REF! | D7: =IFERROR(__xludf.DUMMYFUNCTION("IF( $C7="""", ""{ "" & IF( REGEXMATCH(B7, ""^First\(\)""), "")"", REGEXEXTRACT(B7, ""^First\(([^ )]+)"") ) & "" }"", IF( REGEXMATCH($C7, ""^First\(<""), VLOOKUP(REGEXEXTRACT($C7, ""\(([^)]+)\)""), 'First Set Macro"&"A'!B:D, 3, FALSE), IF( REGEXMATCH($C7, ""^Follow\(<""), VLOOKUP(REGEXEXTRACT($C7, ""\(([^)]+)\)""), 'Follow Set Macros'!B:D, 3, FALSE), ""{ "" & REGEXEXTRACT($C7, ""\(([^)]+)\)"") & "" }"" ) ) ) "),"#REF!") -> #REF!
A8: =ROW() -> 8 | B8: =IF(CFG!D8 = "λ", ("First(λ - λ) ∪ Follow(" & CFG!B8 & ") ="), ("First(" & TEXTJOIN(" ", TRUE, CFG!D8:AB8) & ") =")) -> #REF! | C8: =IFERROR(__xludf.DUMMYFUNCTION("IF( REGEXMATCH(B8, ""^First\(λ - λ\) ∪ Follow\(""), ""Follow("" & REGEXEXTRACT(B8, ""Follow\(([^)]+)\)"") & "") ="", IF( OR( REGEXMATCH(B8, ""^First\([^<]""), REGEXMATCH(B8, ""^First\(<[^A-Za-z_]"") ), """", IF( CFG"&"!D8=""λ"", ""Follow("" & CFG!B8 & "") ="", ""First("" & CFG!D8 & "") ="" ) ) ) "),"#REF!") -> #REF! | D8: =IFERROR(__xludf.DUMMYFUNCTION("IF( $C8="""", ""{ "" & IF( REGEXMATCH(B8, ""^First\(\)""), "")"", REGEXEXTRACT(B8, ""^First\(([^ )]+)"") ) & "" }"", IF( REGEXMATCH($C8, ""^First\(<""), VLOOKUP(REGEXEXTRACT($C8, ""\(([^)]+)\)""), 'First Set Macro"&"A'!B:D, 3, FALSE), IF( REGEXMATCH($C8, ""^Follow\(<""), VLOOKUP(REGEXEXTRACT($C8, ""\(([^)]+)\)""), 'Follow Set Macros'!B:D, 3, FALSE), ""{ "" & REGEXEXTRACT($C8, ""\(([^)]+)\)"") & "" }"" ) ) ) "),"#REF!") -> #REF!
A9: =ROW() -> 9 | B9: =IF(CFG!D9 = "λ", ("First(λ - λ) ∪ Follow(" & CFG!B9 & ") ="), ("First(" & TEXTJOIN(" ", TRUE, CFG!D9:AB9) & ") =")) -> #REF! | C9: =IFERROR(__xludf.DUMMYFUNCTION("IF( REGEXMATCH(B9, ""^First\(λ - λ\) ∪ Follow\(""), ""Follow("" & REGEXEXTRACT(B9, ""Follow\(([^)]+)\)"") & "") ="", IF( OR( REGEXMATCH(B9, ""^First\([^<]""), REGEXMATCH(B9, ""^First\(<[^A-Za-z_]"") ), """", IF( CFG"&"!D9=""λ"", ""Follow("" & CFG!B9 & "") ="", ""First("" & CFG!D9 & "") ="" ) ) ) "),"#REF!") -> #REF! | D9: =IFERROR(__xludf.DUMMYFUNCTION("IF( $C9="""", ""{ "" & IF( REGEXMATCH(B9, ""^First\(\)""), "")"", REGEXEXTRACT(B9, ""^First\(([^ )]+)"") ) & "" }"", IF( REGEXMATCH($C9, ""^First\(<""), VLOOKUP(REGEXEXTRACT($C9, ""\(([^)]+)\)""), 'First Set Macro"&"A'!B:D, 3, FALSE), IF( REGEXMATCH($C9, ""^Follow\(<""), VLOOKUP(REGEXEXTRACT($C9, ""\(([^)]+)\)""), 'Follow Set Macros'!B:D, 3, FALSE), ""{ "" & REGEXEXTRACT($C9, ""\(([^)]+)\)"") & "" }"" ) ) ) "),"#REF!") -> #REF!
A10: =ROW() -> 10 | B10: =IF(CFG!D10 = "λ", ("First(λ - λ) ∪ Follow(" & CFG!B10 & ") ="), ("First(" & TEXTJOIN(" ", TRUE, CFG!D10:AB10) & ") =")) -> #REF! | C10: =IFERROR(__xludf.DUMMYFUNCTION("IF( REGEXMATCH(B10, ""^First\(λ - λ\) ∪ Follow\(""), ""Follow("" & REGEXEXTRACT(B10, ""Follow\(([^)]+)\)"") & "") ="", IF( OR( REGEXMATCH(B10, ""^First\([^<]""), REGEXMATCH(B10, ""^First\(<[^A-Za-z_]"") ), """", IF( "&" CFG!D10=""λ"", ""Follow("" & CFG!B10 & "") ="", ""First("" & CFG!D10 & "") ="" ) ) ) "),"#REF!") -> #REF! | D10: =IFERROR(__xludf.DUMMYFUNCTION("IF( $C10="""", ""{ "" & IF( REGEXMATCH(B10, ""^First\(\)""), "")"", REGEXEXTRACT(B10, ""^First\(([^ )]+)"") ) & "" }"", IF( REGEXMATCH($C10, ""^First\(<""), VLOOKUP(REGEXEXTRACT($C10, ""\(([^)]+)\)""), 'First Set "&"MacroA'!B:D, 3, FALSE), IF( REGEXMATCH($C10, ""^Follow\(<""), VLOOKUP(REGEXEXTRACT($C10, ""\(([^)]+)\)""), 'Follow Set Macros'!B:D, 3, FALSE), ""{ "" & REGEXEXTRACT($C10, ""\(([^)]+)\)"") & "" }"" ) ) ) "),"#REF!") -> #REF!
A11: =ROW() -> 11 | B11: =IF(CFG!D11 = "λ", ("First(λ - λ) ∪ Follow(" & CFG!B11 & ") ="), ("First(" & TEXTJOIN(" ", TRUE, CFG!D11:AB11) & ") =")) -> #REF! | C11: =IFERROR(__xludf.DUMMYFUNCTION("IF( REGEXMATCH(B11, ""^First\(λ - λ\) ∪ Follow\(""), ""Follow("" & REGEXEXTRACT(B11, ""Follow\(([^)]+)\)"") & "") ="", IF( OR( REGEXMATCH(B11, ""^First\([^<]""), REGEXMATCH(B11, ""^First\(<[^A-Za-z_]"") ), """", IF( "&" CFG!D11=""λ"", ""Follow("" & CFG!B11 & "") ="", ""First("" & CFG!D11 & "") ="" ) ) ) "),"#REF!") -> #REF! | D11: =IFERROR(__xludf.DUMMYFUNCTION("IF( $C11="""", ""{ "" & IF( REGEXMATCH(B11, ""^First\(\)""), "")"", REGEXEXTRACT(B11, ""^First\(([^ )]+)"") ) & "" }"", IF( REGEXMATCH($C11, ""^First\(<""), VLOOKUP(REGEXEXTRACT($C11, ""\(([^)]+)\)""), 'First Set "&"MacroA'!B:D, 3, FALSE), IF( REGEXMATCH($C11, ""^Follow\(<""), VLOOKUP(REGEXEXTRACT($C11, ""\(([^)]+)\)""), 'Follow Set Macros'!B:D, 3, FALSE), ""{ "" & REGEXEXTRACT($C11, ""\(([^)]+)\)"") & "" }"" ) ) ) "),"#REF!") -> #REF!
A12: =ROW() -> 12 | B12: =IF(CFG!D12 = "λ", ("First(λ - λ) ∪ Follow(" & CFG!B12 & ") ="), ("First(" & TEXTJOIN(" ", TRUE, CFG!D12:AB12) & ") =")) -> #REF! | C12: =IFERROR(__xludf.DUMMYFUNCTION("IF( REGEXMATCH(B12, ""^First\(λ - λ\) ∪ Follow\(""), ""Follow("" & REGEXEXTRACT(B12, ""Follow\(([^)]+)\)"") & "") ="", IF( OR( REGEXMATCH(B12, ""^First\([^<]""), REGEXMATCH(B12, ""^First\(<[^A-Za-z_]"") ), """", IF( "&" CFG!D12=""λ"", ""Follow("" & CFG!B12 & "") ="", ""First("" & CFG!D12 & "") ="" ) ) ) "),"#REF!") -> #REF! | D12: =IFERROR(__xludf.DUMMYFUNCTION("IF( $C12="""", ""{ "" & IF( REGEXMATCH(B12, ""^First\(\)""), "")"", REGEXEXTRACT(B12, ""^First\(([^ )]+)"") ) & "" }"", IF( REGEXMATCH($C12, ""^First\(<""), VLOOKUP(REGEXEXTRACT($C12, ""\(([^)]+)\)""), 'First Set "&"MacroA'!B:D, 3, FALSE), IF( REGEXMATCH($C12, ""^Follow\(<""), VLOOKUP(REGEXEXTRACT($C12, ""\(([^)]+)\)""), 'Follow Set Macros'!B:D, 3, FALSE), ""{ "" & REGEXEXTRACT($C12, ""\(([^)]+)\)"") & "" }"" ) ) ) "),"#REF!") -> #REF!
A13: =ROW() -> 13 | B13: =IF(CFG!D13 = "λ", ("First(λ - λ) ∪ Follow(" & CFG!B13 & ") ="), ("First(" & TEXTJOIN(" ", TRUE, CFG!D13:AB13) & ") =")) -> #REF! | C13: =IFERROR(__xludf.DUMMYFUNCTION("IF( REGEXMATCH(B13, ""^First\(λ - λ\) ∪ Follow\(""), ""Follow("" & REGEXEXTRACT(B13, ""Follow\(([^)]+)\)"") & "") ="", IF( OR( REGEXMATCH(B13, ""^First\([^<]""), REGEXMATCH(B13, ""^First\(<[^A-Za-z_]"") ), """", IF( "&" CFG!D13=""λ"", ""Follow("" & CFG!B13 & "") ="", ""First("" & CFG!D13 & "") ="" ) ) ) "),"#REF!") -> #REF! | D13: =IFERROR(__xludf.DUMMYFUNCTION("IF( $C13="""", ""{ "" & IF( REGEXMATCH(B13, ""^First\(\)""), "")"", REGEXEXTRACT(B13, ""^First\(([^ )]+)"") ) & "" }"", IF( REGEXMATCH($C13, ""^First\(<""), VLOOKUP(REGEXEXTRACT($C13, ""\(([^)]+)\)""), 'First Set "&"MacroA'!B:D, 3, FALSE), IF( REGEXMATCH($C13, ""^Follow\(<""), VLOOKUP(REGEXEXTRACT($C13, ""\(([^)]+)\)""), 'Follow Set Macros'!B:D, 3, FALSE), ""{ "" & REGEXEXTRACT($C13, ""\(([^)]+)\)"") & "" }"" ) ) ) "),"#REF!") -> #REF!
A14: =ROW() -> 14 | B14: =IF(CFG!D14 = "λ", ("First(λ - λ) ∪ Follow(" & CFG!B14 & ") ="), ("First(" & TEXTJOIN(" ", TRUE, CFG!D14:AB14) & ") =")) -> #REF! | C14: =IFERROR(__xludf.DUMMYFUNCTION("IF( REGEXMATCH(B14, ""^First\(λ - λ\) ∪ Follow\(""), ""Follow("" & REGEXEXTRACT(B14, ""Follow\(([^)]+)\)"") & "") ="", IF( OR( REGEXMATCH(B14, ""^First\([^<]""), REGEXMATCH(B14, ""^First\(<[^A-Za-z_]"") ), """", IF( "&" CFG!D14=""λ"", ""Follow("" & CFG!B14 & "") ="", ""First("" & CFG!D14 & "") ="" ) ) ) "),"#REF!") -> #REF! | D14: =IFERROR(__xludf.DUMMYFUNCTION("IF( $C14="""", ""{ "" & IF( REGEXMATCH(B14, ""^First\(\)""), "")"", REGEXEXTRACT(B14, ""^First\(([^ )]+)"") ) & "" }"", IF( REGEXMATCH($C14, ""^First\(<""), VLOOKUP(REGEXEXTRACT($C14, ""\(([^)]+)\)""), 'First Set "&"MacroA'!B:D, 3, FALSE), IF( REGEXMATCH($C14, ""^Follow\(<""), VLOOKUP(REGEXEXTRACT($C14, ""\(([^)]+)\)""), 'Follow Set Macros'!B:D, 3, FALSE), ""{ "" & REGEXEXTRACT($C14, ""\(([^)]+)\)"") & "" }"" ) ) ) "),"#REF!") -> #REF!
A15: =ROW() -> 15 | B15: =IF(CFG!D15 = "λ", ("First(λ - λ) ∪ Follow(" & CFG!B15 & ") ="), ("First(" & TEXTJOIN(" ", TRUE, CFG!D15:AB15) & ") =")) -> #REF! | C15: =IFERROR(__xludf.DUMMYFUNCTION("IF( REGEXMATCH(B15, ""^First\(λ - λ\) ∪ Follow\(""), ""Follow("" & REGEXEXTRACT(B15, ""Follow\(([^)]+)\)"") & "") ="", IF( OR( REGEXMATCH(B15, ""^First\([^<]""), REGEXMATCH(B15, ""^First\(<[^A-Za-z_]"") ), """", IF( "&" CFG!D15=""λ"", ""Follow("" & CFG!B15 & "") ="", ""First("" & CFG!D15 & "") ="" ) ) ) "),"#REF!") -> #REF! | D15: =IFERROR(__xludf.DUMMYFUNCTION("IF( $C15="""", ""{ "" & IF( REGEXMATCH(B15, ""^First\(\)""), "")"", REGEXEXTRACT(B15, ""^First\(([^ )]+)"") ) & "" }"", IF( REGEXMATCH($C15, ""^First\(<""), VLOOKUP(REGEXEXTRACT($C15, ""\(([^)]+)\)""), 'First Set "&"MacroA'!B:D, 3, FALSE), IF( REGEXMATCH($C15, ""^Follow\(<""), VLOOKUP(REGEXEXTRACT($C15, ""\(([^)]+)\)""), 'Follow Set Macros'!B:D, 3, FALSE), ""{ "" & REGEXEXTRACT($C15, ""\(([^)]+)\)"") & "" }"" ) ) ) "),"#REF!") -> #REF!
A16: =ROW() -> 16 | B16: =IF(CFG!D16 = "λ", ("First(λ - λ) ∪ Follow(" & CFG!B16 & ") ="), ("First(" & TEXTJOIN(" ", TRUE, CFG!D16:AB16) & ") =")) -> #REF! | C16: =IFERROR(__xludf.DUMMYFUNCTION("IF( REGEXMATCH(B16, ""^First\(λ - λ\) ∪ Follow\(""), ""Follow("" & REGEXEXTRACT(B16, ""Follow\(([^)]+)\)"") & "") ="", IF( OR( REGEXMATCH(B16, ""^First\([^<]""), REGEXMATCH(B16, ""^First\(<[^A-Za-z_]"") ), """", IF( "&" CFG!D16=""λ"", ""Follow("" & CFG!B16 & "") ="", ""First("" & CFG!D16 & "") ="" ) ) ) "),"#REF!") -> #REF! | D16: =IFERROR(__xludf.DUMMYFUNCTION("IF( $C16="""", ""{ "" & IF( REGEXMATCH(B16, ""^First\(\)""), "")"", REGEXEXTRACT(B16, ""^First\(([^ )]+)"") ) & "" }"", IF( REGEXMATCH($C16, ""^First\(<""), VLOOKUP(REGEXEXTRACT($C16, ""\(([^)]+)\)""), 'First Set "&"MacroA'!B:D, 3, FALSE), IF( REGEXMATCH($C16, ""^Follow\(<""), VLOOKUP(REGEXEXTRACT($C16, ""\(([^)]+)\)""), 'Follow Set Macros'!B:D, 3, FALSE), ""{ "" & REGEXEXTRACT($C16, ""\(([^)]+)\)"") & "" }"" ) ) ) "),"#REF!") -> #REF!
A17: =ROW() -> 17 | B17: =IF(CFG!D17 = "λ", ("First(λ - λ) ∪ Follow(" & CFG!B17 & ") ="), ("First(" & TEXTJOIN(" ", TRUE, CFG!D17:AB17) & ") =")) -> #REF! | C17: =IFERROR(__xludf.DUMMYFUNCTION("IF( REGEXMATCH(B17, ""^First\(λ - λ\) ∪ Follow\(""), ""Follow("" & REGEXEXTRACT(B17, ""Follow\(([^)]+)\)"") & "") ="", IF( OR( REGEXMATCH(B17, ""^First\([^<]""), REGEXMATCH(B17, ""^First\(<[^A-Za-z_]"") ), """", IF( "&" CFG!D17=""λ"", ""Follow("" & CFG!B17 & "") ="", ""First("" & CFG!D17 & "") ="" ) ) ) "),"#REF!") -> #REF! | D17: =IFERROR(__xludf.DUMMYFUNCTION("IF( $C17="""", ""{ "" & IF( REGEXMATCH(B17, ""^First\(\)""), "")"", REGEXEXTRACT(B17, ""^First\(([^ )]+)"") ) & "" }"", IF( REGEXMATCH($C17, ""^First\(<""), VLOOKUP(REGEXEXTRACT($C17, ""\(([^)]+)\)""), 'First Set "&"MacroA'!B:D, 3, FALSE), IF( REGEXMATCH($C17, ""^Follow\(<""), VLOOKUP(REGEXEXTRACT($C17, ""\(([^)]+)\)""), 'Follow Set Macros'!B:D, 3, FALSE), ""{ "" & REGEXEXTRACT($C17, ""\(([^)]+)\)"") & "" }"" ) ) ) "),"#REF!") -> #REF!
A18: =ROW() -> 18 | B18: =IF(CFG!D18 = "λ", ("First(λ - λ) ∪ Follow(" & CFG!B18 & ") ="), ("First(" & TEXTJOIN(" ", TRUE, CFG!D18:AB18) & ") =")) -> #REF! | C18: =IFERROR(__xludf.DUMMYFUNCTION("IF( REGEXMATCH(B18, ""^First\(λ - λ\) ∪ Follow\(""), ""Follow("" & REGEXEXTRACT(B18, ""Follow\(([^)]+)\)"") & "") ="", IF( OR( REGEXMATCH(B18, ""^First\([^<]""), REGEXMATCH(B18, ""^First\(<[^A-Za-z_]"") ), """", IF( "&" CFG!D18=""λ"", ""Follow("" & CFG!B18 & "") ="", ""First("" & CFG!D18 & "") ="" ) ) ) "),"#REF!") -> #REF! | D18: =IFERROR(__xludf.DUMMYFUNCTION("IF( $C18="""", ""{ "" & IF( REGEXMATCH(B18, ""^First\(\)""), "")"", REGEXEXTRACT(B18, ""^First\(([^ )]+)"") ) & "" }"", IF( REGEXMATCH($C18, ""^First\(<""), VLOOKUP(REGEXEXTRACT($C18, ""\(([^)]+)\)""), 'First Set "&"MacroA'!B:D, 3, FALSE), IF( REGEXMATCH($C18, ""^Follow\(<""), VLOOKUP(REGEXEXTRACT($C18, ""\(([^)]+)\)""), 'Follow Set Macros'!B:D, 3, FALSE), ""{ "" & REGEXEXTRACT($C18, ""\(([^)]+)\)"") & "" }"" ) ) ) "),"#REF!") -> #REF!
A19: =ROW() -> 19 | B19: =IF(CFG!D19 = "λ", ("First(λ - λ) ∪ Follow(" & CFG!B19 & ") ="), ("First(" & TEXTJOIN(" ", TRUE, CFG!D19:AB19) & ") =")) -> #REF! | C19: =IFERROR(__xludf.DUMMYFUNCTION("IF( REGEXMATCH(B19, ""^First\(λ - λ\) ∪ Follow\(""), ""Follow("" & REGEXEXTRACT(B19, ""Follow\(([^)]+)\)"") & "") ="", IF( OR( REGEXMATCH(B19, ""^First\([^<]""), REGEXMATCH(B19, ""^First\(<[^A-Za-z_]"") ), """", IF( "&" CFG!D19=""λ"", ""Follow("" & CFG!B19 & "") ="", ""First("" & CFG!D19 & "") ="" ) ) ) "),"#REF!") -> #REF! | D19: =IFERROR(__xludf.DUMMYFUNCTION("IF( $C19="""", ""{ "" & IF( REGEXMATCH(B19, ""^First\(\)""), "")"", REGEXEXTRACT(B19, ""^First\(([^ )]+)"") ) & "" }"", IF( REGEXMATCH($C19, ""^First\(<""), VLOOKUP(REGEXEXTRACT($C19, ""\(([^)]+)\)""), 'First Set "&"MacroA'!B:D, 3, FALSE), IF( REGEXMATCH($C19, ""^Follow\(<""), VLOOKUP(REGEXEXTRACT($C19, ""\(([^)]+)\)""), 'Follow Set Macros'!B:D, 3, FALSE), ""{ "" & REGEXEXTRACT($C19, ""\(([^)]+)\)"") & "" }"" ) ) ) "),"#REF!") -> #REF!
